<?xml version="1.0" ?>
<!-- =================================================================================== -->
<!-- |    This document was autogenerated by xacro from mobile_base.urdf.xacro         | -->
<!-- |    EDITING THIS FILE BY HAND IS NOT RECOMMENDED                                 | -->
<!-- =================================================================================== -->
<robot name="sixdof_arm">
  <ros2_control name="GazeboSimSystem" type="system">
    <hardware>
      <plugin>gazebo_ros2_control/GazeboSystem</plugin>
    </hardware>
    <joint name="base_arm1_joint">
      <command_interface name="position">
        <param name="min">0</param>
        <param name="max">3.141592653589793</param>
      </command_interface>
      <command_interface name="velocity">
        <param name="min">-1</param>
        <param name="max">1</param>
      </command_interface>
      <state_interface name="position">
        <param name="initial_value">0.0</param>
      </state_interface>
      <state_interface name="velocity">
        <param name="initial_value">0.0</param>
      </state_interface>
    </joint>
    <joint name="arm1_arm2_joint">
      <command_interface name="position">
        <param name="min">0</param>
        <param name="max">3.141592653589793</param>
      </command_interface>
      <command_interface name="velocity">
        <param name="min">-1</param>
        <param name="max">1</param>
      </command_interface>
      <state_interface name="position">
        <param name="initial_value">0.0</param>
      </state_interface>
      <state_interface name="velocity">
        <param name="initial_value">0.0</param>
      </state_interface>
    </joint>
    <joint name="arm2_arm3_joint">
      <command_interface name="position">
        <param name="min">0</param>
        <param name="max">3.141592653589793</param>
      </command_interface>
      <command_interface name="velocity">
        <param name="min">-1</param>
        <param name="max">1</param>
      </command_interface>
      <state_interface name="position">
        <param name="initial_value">0.0</param>
      </state_interface>
      <state_interface name="velocity">
        <param name="initial_value">0.0</param>
      </state_interface>
    </joint>
    <joint name="arm3_arm4_joint">
      <command_interface name="position">
        <param name="min">0</param>
        <param name="max">3.141592653589793</param>
      </command_interface>
      <command_interface name="velocity">
        <param name="min">0</param>
        <param name="max">1</param>
      </command_interface>
      <state_interface name="position">
        <param name="initial_value">0.0</param>
      </state_interface>
      <state_interface name="velocity">
        <param name="initial_value">0.0</param>
      </state_interface>
    </joint>
    <joint name="arm4_arm5_joint">
      <command_interface name="position">
        <param name="min">0</param>
        <param name="max">3.141592653589793</param>
      </command_interface>
      <command_interface name="velocity">
        <param name="min">0</param>
        <param name="max">1</param>
      </command_interface>
      <state_interface name="position">
        <param name="initial_value">0.0</param>
      </state_interface>
      <state_interface name="velocity">
        <param name="initial_value">0.0</param>
      </state_interface>
    </joint>
    <joint name="arm5_arm6_joint">
      <command_interface name="position">
        <param name="min">0</param>
        <param name="max">3.141592653589793</param>
      </command_interface>
      <command_interface name="velocity">
        <param name="min">0</param>
        <param name="max">1</param>
      </command_interface>
      <state_interface name="position">
        <param name="initial_value">0.0</param>
      </state_interface>
      <state_interface name="velocity">
        <param name="initial_value">0.0</param>
      </state_interface>
    </joint>
    <joint name="arm6_gripper1_joint">
      <command_interface name="position">
        <param name="min">-0.7853981633974483</param>
        <param name="max">-1.5707963267948966</param>
      </command_interface>
      <command_interface name="velocity">
        <param name="min">0</param>
        <param name="max">1</param>
      </command_interface>
      <state_interface name="position">
        <param name="initial_value">0.0</param>
      </state_interface>
      <state_interface name="velocity">
        <param name="initial_value">0.0</param>
      </state_interface>
    </joint>
    <joint name="arm6_gripper2_joint">
      <command_interface name="position">
        <param name="min">1.5707963267948966</param>
        <param name="max">2.356194490192345</param>
      </command_interface>
      <command_interface name="velocity">
        <param name="min">0</param>
        <param name="max">1</param>
      </command_interface>
      <state_interface name="position">
        <param name="initial_value">0.0</param>
      </state_interface>
      <state_interface name="velocity">
        <param name="initial_value">0.0</param>
      </state_interface>
    </joint>
  </ros2_control>
  <gazebo>
    <plugin filename="libgazebo_ros2_control.so" name="gazebo_ros2_control">
      <parameters>/home/livia/rl_6dof_ws/install/sixdof_arm_description/share/sixdof_arm_description/config/sixdof_arm_controllers.yaml</parameters>
    </plugin>
  </gazebo>
  <material name="light_black">
    <color rgba="0.5 0.5 0.5 1.0"/>
  </material>
  <material name="salmon">
    <color rgba="0.8754 0.4471 0.3176 1.0"/>
  </material>
  <material name="yellow">
    <color rgba="1 0.7569 0.0549 1.0"/>
  </material>
  <material name="purple">
    <color rgba="0.6824 0.3333 0.7373 1.0"/>
  </material>
  <material name="green">
    <color rgba="0.3725 0.6549 0.2392 1.0"/>
  </material>
  <material name="blue">
    <color rgba="0.3686 0.2509 0.6431 1.0"/>
  </material>
  <material name="blue_tifany">
    <color rgba="0.5372 0.8549 0.8274 1.0"/>
  </material>
  <gazebo reference="base_link">
    <selfCollide>true</selfCollide>
    <visual>
      <material>
        <ambient>0.5 0.5 0.5</ambient>
        <diffuse>0.9 0.6 0.45 1</diffuse>
        <specular>0.95 0.95 0.95 1</specular>
        <emissive>0 0 0 0</emissive>
      </material>
      <mu1>0.2</mu1>
      <mu2>0.2</mu2>
      <self_collide>true</self_collide>
      <gravity>true</gravity>
    </visual>
  </gazebo>
  <gazebo reference="arm1_link">
    <selfCollide>true</selfCollide>
    <visual>
      <material>
        <ambient>0.8754 0.4471 0.3176</ambient>
        <diffuse>0.9 0.6 0.45 1</diffuse>
        <specular>0.95 0.95 0.95 1</specular>
        <emissive>0 0 0 0</emissive>
      </material>
      <mu1>0.2</mu1>
      <mu2>0.2</mu2>
      <self_collide>true</self_collide>
      <gravity>true</gravity>
    </visual>
  </gazebo>
  <gazebo reference="arm2_link">
    <selfCollide>true</selfCollide>
    <visual>
      <material>
        <ambient>1 0.7569 0.0549</ambient>
        <diffuse>0.9 0.6 0.45 1</diffuse>
        <specular>0.95 0.95 0.95 1</specular>
        <emissive>0 0 0 0</emissive>
      </material>
      <mu1>0.2</mu1>
      <mu2>0.2</mu2>
      <self_collide>true</self_collide>
      <gravity>true</gravity>
    </visual>
  </gazebo>
  <gazebo reference="arm3_link">
    <selfCollide>true</selfCollide>
    <visual>
      <material>
        <ambient>0.6824 0.3333 0.7373</ambient>
        <diffuse>0.9 0.6 0.45 1</diffuse>
        <specular>0.95 0.95 0.95 1</specular>
        <emissive>0 0 0 0</emissive>
      </material>
      <mu1>0.2</mu1>
      <mu2>0.2</mu2>
      <self_collide>true</self_collide>
      <gravity>true</gravity>
    </visual>
  </gazebo>
  <gazebo reference="arm4_link">
    <selfCollide>true</selfCollide>
    <visual>
      <material>
        <ambient>0.3725 0.6549 0.2392</ambient>
        <diffuse>0.9 0.6 0.45 1</diffuse>
        <specular>0.95 0.95 0.95 1</specular>
        <emissive>0 0 0 0</emissive>
      </material>
      <mu1>0.2</mu1>
      <mu2>0.2</mu2>
      <self_collide>true</self_collide>
      <gravity>true</gravity>
    </visual>
  </gazebo>
  <gazebo reference="arm5_link">
    <selfCollide>true</selfCollide>
    <visual>
      <material>
        <ambient>0.3686 0.2509 0.6431</ambient>
        <diffuse>0.9 0.6 0.45 1</diffuse>
        <specular>0.95 0.95 0.95 1</specular>
        <emissive>0 0 0 0</emissive>
      </material>
      <mu1>0.2</mu1>
      <mu2>0.2</mu2>
      <self_collide>true</self_collide>
      <gravity>true</gravity>
    </visual>
  </gazebo>
  <gazebo reference="arm6_link">
    <selfCollide>true</selfCollide>
    <visual>
      <material>
        <ambient>0.5372 0.8549 0.8274</ambient>
        <diffuse>0.9 0.6 0.45 1</diffuse>
        <specular>0.95 0.95 0.95 1</specular>
        <emissive>0 0 0 0</emissive>
      </material>
      <mu1>0.2</mu1>
      <mu2>0.2</mu2>
      <self_collide>true</self_collide>
      <gravity>true</gravity>
    </visual>
  </gazebo>
  <gazebo reference="gripper1_link">
    <selfCollide>true</selfCollide>
    <visual>
      <material>
        <ambient>0.5 0.5 0.5</ambient>
        <diffuse>0.9 0.6 0.45 1</diffuse>
        <specular>0.95 0.95 0.95 1</specular>
        <emissive>0 0 0 0</emissive>
      </material>
      <mu1>0.2</mu1>
      <mu2>0.2</mu2>
      <self_collide>true</self_collide>
      <gravity>true</gravity>
    </visual>
  </gazebo>
  <gazebo reference="gripper2_link">
    <selfCollide>true</selfCollide>
    <visual>
      <material>
        <ambient>0.5 0.5 0.5</ambient>
        <diffuse>0.9 0.6 0.45 1</diffuse>
        <specular>0.95 0.95 0.95 1</specular>
        <emissive>0 0 0 0</emissive>
      </material>
      <mu1>0.2</mu1>
      <mu2>0.2</mu2>
      <self_collide>true</self_collide>
      <gravity>true</gravity>
    </visual>
  </gazebo>
  <link name="base_link">
    <visual>
      <geometry>
        <mesh filename="package://sixdof_arm_description/meshes/sixdof_arm/base_link.stl" scale="1 1 1"/>
      </geometry>
      <origin rpy="0 0 0" xyz="0 0 0.04"/>
      <material name="light_black"/>
    </visual>
    <inertial>
      <origin rpy="0 0 0" xyz="0 2.679e-8 0.01026544"/>
      <mass value="10.6734184"/>
      <inertia ixx="0.05702778" ixy="0" ixz="0" iyy="0.05702779" iyz="0" izz="0.10703462"/>
    </inertial>
    <collision>
      <geometry>
        <cylinder length="0.07" radius="0.15"/>
      </geometry>
      <origin rpy="0 0 0" xyz="0 0 0.035"/>
    </collision>
  </link>
  <link name="arm1_link">
    <visual>
      <geometry>
        <mesh filename="package://sixdof_arm_description/meshes/sixdof_arm/link_1.stl" scale="1 1 1"/>
      </geometry>
      <origin rpy="0 0 0" xyz="0 0 0"/>
      <material name="salmon"/>
    </visual>
    <inertial>
      <origin rpy="0 0 0" xyz="0 -0.00016159 0.14671717"/>
      <mass value="16.02392927"/>
      <inertia ixx="0.13097774" ixy="-1.354e-8" ixz="0" iyy="0.11390137" iyz="0.00013796" izz="0.06378491"/>
    </inertial>
    <collision>
      <geometry>
        <box size="0.15 0.20 0.275"/>
      </geometry>
      <origin rpy="0 0 0" xyz="0 0 0.1375"/>
    </collision>
  </link>
  <link name="arm2_link">
    <visual>
      <geometry>
        <mesh filename="package://sixdof_arm_description/meshes/sixdof_arm/link_2.stl" scale="1 1 1"/>
      </geometry>
      <origin rpy="0 0 -1.5707963267948966" xyz="0 0 0"/>
      <material name="yellow"/>
    </visual>
    <inertial>
      <origin rpy="0 0 -1.5707963267948966" xyz="-0.00008884 0 0.47100021"/>
      <mass value="58.29018559"/>
      <inertia ixx="6.62579145" ixy="0.0000054" ixz="0" iyy="6.65994246" iyz="-4e-8" izz="0.20137485"/>
    </inertial>
    <collision>
      <geometry>
        <box size="0.15 0.20 1.10"/>
      </geometry>
      <origin rpy="0 0 0" xyz="0 0 0.475"/>
    </collision>
  </link>
  <link name="arm3_link">
    <visual>
      <geometry>
        <mesh filename="package://sixdof_arm_description/meshes/sixdof_arm/link_3.stl" scale="1 1 1"/>
      </geometry>
      <origin rpy="0 1.5707963267948966 0" xyz="0 0 0"/>
      <material name="purple"/>
    </visual>
    <inertial>
      <origin rpy="0 1.5707963267948966 0" xyz="0.325 0 -0.00011793"/>
      <mass value="43.97624328"/>
      <inertia ixx="0.16111702" ixy="0" ixz="-9.935e-8" iyy="2.67279881" iyz="5.713e-9" izz="2.70695549"/>
    </inertial>
    <collision>
      <geometry>
        <box size="0.15 0.20 0.80"/>
      </geometry>
      <origin rpy="0 1.5707963267948966 0" xyz="0.325 0 0"/>
    </collision>
  </link>
  <link name="arm4_link">
    <visual>
      <geometry>
        <mesh filename="package://sixdof_arm_description/meshes/sixdof_arm/link_4.stl" scale="1 1 1"/>
      </geometry>
      <origin rpy="3.141592653589793 0 0" xyz="0 0 0"/>
      <material name="green"/>
    </visual>
    <inertial>
      <origin rpy="3.141592653589793 0 0" xyz="0 0.0010614 -0.05328286"/>
      <mass value="16.02394366"/>
      <inertia ixx="0.13101946" ixy="1.335e-8" ixz="-2.826e-9" iyy="0.11390118" iyz="-0.00166483" izz="0.06382633"/>
    </inertial>
    <collision>
      <geometry>
        <box size="0.15 0.20 0.275"/>
      </geometry>
      <origin rpy="0 0 0" xyz="0 0 -0.0625"/>
    </collision>
  </link>
  <link name="arm5_link">
    <visual>
      <geometry>
        <mesh filename="package://sixdof_arm_description/meshes/sixdof_arm/link_5.stl" scale="1 1 1"/>
      </geometry>
      <origin rpy="3.141592653589793 0 3.141592653589793" xyz="0 0 0"/>
      <material name="blue"/>
    </visual>
    <inertial>
      <origin rpy="3.141592653589793 0 3.141592653589793" xyz="-0.0002301 0 -0.08772699"/>
      <mass value="11.25261767"/>
      <inertia ixx="0.03965941" ixy="2.335e-9" ixz="0.00003178" iyy="0.05673546" iyz="-6.760e-10" izz="0.05036553"/>
    </inertial>
    <collision>
      <geometry>
        <box size="0.20 0.15 0.175"/>
      </geometry>
      <origin rpy="0 0 0" xyz="0 0 -0.0875"/>
    </collision>
  </link>
  <link name="arm6_link">
    <visual>
      <geometry>
        <mesh filename="package://sixdof_arm_description/meshes/sixdof_arm/link_6.stl" scale="1 1 1"/>
      </geometry>
      <origin rpy="0 0 0" xyz="0 0 0"/>
      <material name="blue_tifany"/>
    </visual>
    <inertial>
      <origin rpy="0 0 0" xyz="0 0 0.10531595"/>
      <mass value="9.94813346"/>
      <inertia ixx="0.05211159" ixy="0" ixz="0" iyy="0.05197757" iyz="0" izz="0.02702159"/>
    </inertial>
    <collision>
      <geometry>
        <box size="0.15 0.15 0.20"/>
      </geometry>
      <origin rpy="0 0 0" xyz="0 0 0.10"/>
    </collision>
  </link>
  <link name="gripper1_link">
    <visual>
      <geometry>
        <mesh filename="package://sixdof_arm_description/meshes/sixdof_arm/gripper.stl" scale="1 1 1"/>
      </geometry>
      <origin rpy="0 1.5707963267948966 0" xyz="0 0 0"/>
      <material name="light_black"/>
    </visual>
    <inertial>
      <origin rpy="0 0 0" xyz="-0.0075 0.090250025 0.027995235"/>
      <mass value="0.23129816"/>
      <inertia ixx="0.00058838" ixy="-0.00002395" ixz="0" iyy="0.00007385" iyz="0" izz="0.00065355"/>
    </inertial>
    <collision>
      <geometry>
        <box size="0.015 0.16050005 0.07295455"/>
      </geometry>
      <origin rpy="0 0 0" xyz="-0.0075 0.090250025 0.027995235"/>
    </collision>
  </link>
  <link name="gripper2_link">
    <visual>
      <geometry>
        <mesh filename="package://sixdof_arm_description/meshes/sixdof_arm/gripper.stl" scale="1 1 1"/>
      </geometry>
      <origin rpy="0 1.5707963267948966 0" xyz="0 0 0"/>
      <material name="light_black"/>
    </visual>
    <inertial>
      <origin rpy="0 0 0" xyz="-0.0075 0.090250025 0.027995235"/>
      <mass value="0.23129816"/>
      <inertia ixx="0.00058838" ixy="-0.00002395" ixz="0" iyy="0.00007385" iyz="0" izz="0.00065355"/>
    </inertial>
    <collision name="gripper2_link_collision">
      <geometry>
        <box size="0.015 0.16050005 0.07295455"/>
      </geometry>
      <origin rpy="0 0 0" xyz="-0.0075 0.090250025 0.027995235"/>
    </collision>
  </link>
  <link name="world"/>
  <joint name="world_base_joint" type="fixed">
    <origin rpy="0 0 0" xyz="0 0 0"/>
    <parent link="world"/>
    <child link="base_link"/>
  </joint>
  <joint name="base_arm1_joint" type="revolute">
    <parent link="base_link"/>
    <child link="arm1_link"/>
    <origin rpy="0 0 0" xyz="0 0 0.07"/>
    <axis xyz="0 0 1"/>
    <limit effort="10" lower="0" upper="3.141592653589793" velocity="1.0"/>
  </joint>
  <joint name="arm1_arm2_joint" type="revolute">
    <parent link="arm1_link"/>
    <child link="arm2_link"/>
    <origin rpy="0 0 0" xyz="0 -0.20 0.20"/>
    <axis xyz="0 1 0"/>
    <limit effort="100" lower="0" upper="3.141592653589793" velocity="1.0"/>
  </joint>
  <joint name="arm2_arm3_joint" type="revolute">
    <parent link="arm2_link"/>
    <child link="arm3_link"/>
    <origin rpy="0 0 0" xyz="0 0.20 0.95"/>
    <axis xyz="0 1 0"/>
    <limit effort="10" lower="0" upper="3.141592653589793" velocity="1.0"/>
  </joint>
  <joint name="arm3_arm4_joint" type="revolute">
    <parent link="arm3_link"/>
    <child link="arm4_link"/>
    <origin rpy="0 -1.5707963267948966 0" xyz="0.65 -0.20 0"/>
    <axis xyz="0 1 0"/>
    <limit effort="10" lower="0" upper="3.141592653589793" velocity="1.0"/>
  </joint>
  <joint name="arm4_arm5_joint" type="revolute">
    <parent link="arm4_link"/>
    <child link="arm5_link"/>
    <origin rpy="0 0 3.141592653589793" xyz="0 0 -0.20"/>
    <axis xyz="0 0 1"/>
    <limit effort="10" lower="0" upper="3.141592653589793" velocity="1.0"/>
  </joint>
  <joint name="arm5_arm6_joint" type="revolute">
    <parent link="arm5_link"/>
    <child link="arm6_link"/>
    <origin rpy="0 1.5707963267948966 0" xyz="0.10 0 -0.1"/>
    <axis xyz="0 0 1"/>
    <limit effort="10" lower="0" upper="3.141592653589793" velocity="1.0"/>
  </joint>
  <joint name="arm6_gripper1_joint" type="revolute">
    <parent link="arm6_link"/>
    <child link="gripper1_link"/>
    <origin rpy="0 3.141592653589793 0" xyz="-0.0075 0.025 0.245"/>
    <axis xyz="1 0 0"/>
    <limit effort="10" lower="-0.7853981633974483" upper="-1.5707963267948966" velocity="1.0"/>
  </joint>
  <joint name="arm6_gripper2_joint" type="revolute">
    <parent link="arm6_link"/>
    <child link="gripper2_link"/>
    <origin rpy="0 0 0" xyz="0.0075 -0.025 0.245"/>
    <axis xyz="1 0 0"/>
    <limit effort="10" lower="1.5707963267948966" upper="2.356194490192345" velocity="1.0"/>
  </joint>
  <transmission name="transmission_base_arm1">
    <type>transmission_interface/SimpleTransmission</type>
    <joint name="base_arm1_joint">
      <hardwareInterface>velocity</hardwareInterface>
    </joint>
  </transmission>
  <transmission name="transmission_arm1_arm2_joint">
    <type>transmission_interface/SimpleTransmission</type>
    <joint name="arm1_arm2_joint">
      <hardwareInterface>velocity</hardwareInterface>
    </joint>
  </transmission>
  <transmission name="transmission_arm2_arm3_joint">
    <type>transmission_interface/SimpleTransmission</type>
    <joint name="arm2_arm3_joint">
      <hardwareInterface>velocity</hardwareInterface>
    </joint>
  </transmission>
  <transmission name="transmission_arm3_arm4_joint">
    <type>transmission_interface/SimpleTransmission</type>
    <joint name="arm3_arm4_joint">
      <hardwareInterface>velocity</hardwareInterface>
    </joint>
  </transmission>
  <transmission name="transmission_arm4_arm5_joint">
    <type>transmission_interface/SimpleTransmission</type>
    <joint name="arm4_arm5_joint">
      <hardwareInterface>velocity</hardwareInterface>
    </joint>
  </transmission>
  <transmission name="transmission_arm5_arm6_joint">
    <type>transmission_interface/SimpleTransmission</type>
    <joint name="arm5_arm6_joint">
      <hardwareInterface>velocity</hardwareInterface>
    </joint>
  </transmission>
  <transmission name="transmission_arm6_gripper1_joint">
    <type>transmission_interface/SimpleTransmission</type>
    <joint name="arm6_gripper1_joint">
      <hardwareInterface>velocity</hardwareInterface>
    </joint>
  </transmission>
  <transmission name="transmission_arm6_gripper2_joint">
    <type>transmission_interface/SimpleTransmission</type>
    <joint name="arm6_gripper2_joint">
      <hardwareInterface>velocity</hardwareInterface>
    </joint>
  </transmission>
  <gazebo reference="gripper2_link">
    <sensor name="bumper" type="contact">
      <always_on>true</always_on>
      <update_rate>50</update_rate>
      <contact>
        <collision>gripper2_link_collision</collision>
        <topic>gripper2_contact</topic>
      </contact>
      <plugin filename="libgazebo_ros_bumper.so" name="contact_plugin">
        <alwaysOn>true</alwaysOn>
        <update_rate>100.0</update_rate>
        <frameName>gripper2_link</frameName>
        <bumperTopicName>/sh/contacts/gripper2_link_contact</bumperTopicName>
      </plugin>
    </sensor>
  </gazebo>
</robot>
